Workbook
Name lu_Assets: Lookups!$C$2:$C$12
Name lu_DeliveryModels: Lookups!$D$2:$D$5
Name lu_Departments: Lookups!$A$2:$A$5
Name lu_Disciplines: Lookups!$B$2:$B$9
Name lu_HealthStatus: Lookups!$F$2:$F$4
Name lu_ProjectType: Lookups!$J$2:$J$3
Name lu_RegisterStatus: Lookups!$G$2:$G$3
Name lu_RiskCategory: Lookups!$I$2:$I$7
Name lu_StageGates: Lookups!$E$2:$E$7
Name lu_WorkflowStatus: Lookups!$H$2:$H$6

Sheet README
A1: PDI Dashboard - Backend Data Workbook
A3: Purpose | B3: Single source of truth feeding the Power BI Desktop report and the Excel-native views of the Engineering & Projects Portfolio Hub.
A4: As-of date | B4: All 'current' figures in this dummy dataset (progress %, overdue flags, KPI snapshots) are calculated as of the date in Config!B2, not TODAY(). Change that one cell to move the whole dataset's story forward.
A5: Folder links | B5: Set Config!B3 to your OneDrive 'Project Files' parent folder URL once. Every project's FolderLink column then builds automatically from Config!B3 + Projects!FolderName (see Projects sheet).
A6: Data volume | B6: Data is fully populated/realistic dummy data across 31 tracked projects (24 active + 7 closeout), 52 people, 400+ deliverables, 30+ risks, 100+ milestones and schedule activities, and a 12-month S-curve per active project. Six projects (PRJ-024, PRJ-021, PRJ-018, PRJ-015, PRJ-011, GLB-003) and their headline numbers are taken verbatim from the original HTML mockup; everything else is realistic invented data generated for a working demo, and totals will not match the mockup's placeholder KPI numbers to the digit since those were never wired to real records.
A8: Sheet | B8: What it is
A9: Config | B9: Two settings you edit: AsOfDate and OneDriveBaseURL.
A10: Lookups | B10: Dropdown/reference lists used for data validation and Power BI slicers.
A11: Projects | B11: Master project register - one row per tracked project. Everything else hangs off ProjectID.
A12: People | B12: Division headcount (engineering disciplines + PM/Services/CRV).
A13: Allocations | B13: Bridge table: who is working on which project, at what %.
A14: Deliverables | B14: Master Deliverables Register (MDR) - one row per document/deliverable.
A15: Risks | B15: Risk register (RAID log).
... A23: Build order | B23: This workbook is fully populated end-to-end, but the Power BI report is being built in phases: Phase 1 = Home + Active Projects (portfolio) pages. Later phases wire up Project 360, Deliverables/MDR, Schedule & Controls, Resources and Risks pages using tables already in this workbook.

Sheet Config
A1: Setting | B1: Value
A2: AsOfDate | B2: 46249
A3: OneDriveBaseURL | B3: PASTE-YOUR-ONEDRIVE-PROJECT-FILES-FOLDER-URL-HERE

Sheet Lookups
A1: Departments | B1: Disciplines | C1: Assets | D1: DeliveryModels | E1: StageGates | F1: HealthStatus | G1: RegisterStatus | H1: WorkflowStatus | I1: RiskCategory | J1: ProjectType
A2: Engineering | B2: Process | C2: OML 1 | D2: In-house | E2: Identify | F2: Green | G2: Active | H2: Internal Development | I2: Schedule | J2: Asset Project
A3: Project Services | B3: Mechanical | C3: OML 2 | D3: In-house -> Contractor | E3: Assess | F3: Amber | G3: Closeout | H3: Issued for Review | I3: Cost | J3: Global Initiative
A4: Project Execution | B4: Piping | C4: OML 3 | D4: Contractor-led | E4: Select | F4: Red | H4: Comments Received | I4: Execution
A5: CRV | B5: Instrumentation | C5: OML 4 | D5: Hybrid | E5: Define | H5: Revise & Resubmit | I5: Technical
B6: Electrical | C6: OML 5 | E6: Execute | H6: Approved / IFI | I6: Safety
B7: Civil / Structural | C7: OML 6 | E7: Operate | I7: Commercial
B8: Pipeline | C8: OML 7
B9: Project Engineering | C9: OML 8
C10: OML 9
C11: OML 10
C12: Global

Sheet Projects
A1: ProjectID | B1: ProjectName | C1: ShortDescription | D1: Asset | E1: Department | F1: DeliveryModel | G1: ProjectType | H1: StageGate | I1: PortfolioPhase | J1: RegisterStatus | K1: ProjectManager | L1: LeadEngineer | M1: PlannedProgressPct | N1: ActualProgressPct | O1: ScheduleVarianceDays | P1: HealthStatus | Q1: StartDate | R1: PlannedCompletionDate | S1: ForecastCompletionDate | T1: DeliverablesTotal | U1: DeliverablesComplete | V1: DeliverablesOverdue | W1: OpenRisksCount | X1: ResourceHeadcount | Y1: MDRClosedPct | Z1: PunchItems | AA1: LessonsLearnedStatus | AB1: ScopeDescription | AC1: FolderName | AD1: FolderLink | AE1: FolderURL
A2: PRJ-024 | B2: North Hub Compression Upgrade | C2: Compression upgrade | D2: OML 4 | E2: Engineering | F2: In-house -> Contractor | G2: Asset Project | H2: Define | I2: =IF(J2="Closeout","Closeout / Archive",IF(H2="Define","Define",IF(H2="Execute","Execute","Concept / Assess"))) -> Define | J2: Active | K2: O. Adeyemi | L2: A. Musa | M2: 72 | N2: 68 | O2: 6 | P2: Amber | Q2: 45945 | R2: 46263 | S2: 46269 | T2: =COUNTIF(Deliverables!$B$2:$B$563,A2) -> 22 | U2: =COUNTIFS(Deliverables!$B$2:$B$563,A2,Deliverables!$I$2:$I$563,"Approved / IFI") -> 18 | V2: =COUNTIFS(Deliverables!$B$2:$B$563,A2,Deliverables!$I$2:$I$563,"<>Approved / IFI",Deliverables!$H$2:$H$563,"<"&Config!$B$2) -> 1 | W2: =COUNTIFS(Risks!$B$2:$B$35,A2,Risks!$K$2:$K$35,"Open") -> 4 | X2: =COUNTIF(Allocations!$C$2:$C$73,A2) -> 6 | Y2: =IF(T2=0,0,ROUND(U2/T2*100,0)) -> 82 | Z2: 0 | AA2: Pending | AB2: Upgrade of the existing compression train to increase gas handling capacity and improve operating reliability. Scope includes process simulation, equipment selection, piping modification, E&I design and execution support. | AC2: =A2&" - "&B2 -> PRJ-024 - North Hub Compression Upgrade | AD2: =HYPERLINK(Config!$B$3&"/"&AC2,"Open project folder") -> Open project folder | AE2: =Config!$B$3&"/"&AC2 -> PASTE-YOUR-ONEDRIVE-PROJECT-FILES-FOLDER-URL-HERE/PRJ-024 - North Hub Compression Upgrade
A3: PRJ-021 | B3: Offshore Water Injection | C3: Brownfield modification | D3: OML 7 | E3: Project Execution | F3: Hybrid | G3: Asset Project | H3: Execute | I3: =IF(J3="Closeout","Closeout / Archive",IF(H3="Define","Define",IF(H3="Execute","Execute","Concept / Assess"))) -> Execute | J3: Active | K3: T. Ibrahim | L3: F. Etim | M3: 75 | N3: 74 | O3: -2 | P3: Green | Q3: 45787 | R3: 46336 | S3: 46332 | T3: =COUNTIF(Deliverables!$B$2:$B$563,A3) -> 22 | U3: =COUNTIFS(Deliverables!$B$2:$B$563,A3,Deliverables!$I$2:$I$563,"Approved / IFI") -> 14 | V3: =COUNTIFS(Deliverables!$B$2:$B$563,A3,Deliverables!$I$2:$I$563,"<>Approved / IFI",Deliverables!$H$2:$H$563,"<"&Config!$B$2) -> 1 | W3: =COUNTIFS(Risks!$B$2:$B$35,A3,Risks!$K$2:$K$35,"Open") -> 1 | X3: =COUNTIF(Allocations!$C$2:$C$73,A3) -> 6 | Y3: =IF(T3=0,0,ROUND(U3/T3*100,0)) -> 64 | Z3: 0 | AA3: Pending | AB3: Brownfield modification of the offshore water injection system to restore injection capacity and support reservoir pressure maintenance. | AC3: =A3&" - "&B3 -> PRJ-021 - Offshore Water Injection | AD3: =HYPERLINK(Config!$B$3&"/"&AC3,"Open project folder") -> Open project folder | AE3: =Config!$B$3&"/"&AC3 -> PASTE-YOUR-ONEDRIVE-PROJECT-FILES-FOLDER-URL-HERE/PRJ-021 - Offshore Water Injection
A4: PRJ-018 | B4: Produced Water Upgrade | C4: Process debottlenecking | D4: OML 2 | E4: Engineering | F4: In-house | G4: Asset Project | H4: Assess | I4: =IF(J4="Closeout","Closeout / Archive",IF(H4="Define","Define",IF(H4="Execute","Execute","Concept / Assess"))) -> Concept / Assess | J4: Active | K4: A. Okoro | L4: G. Chukwu | M4: 43 | N4: 37 | O4: 0 | P4: Green | Q4: 46193 | R4: 46438 | S4: 46438 | T4: =COUNTIF(Deliverables!$B$2:$B$563,A4) -> 19 | U4: =COUNTIFS(Deliverables!$B$2:$B$563,A4,Deliverables!$I$2:$I$563,"Approved / IFI") -> 9 | V4: =COUNTIFS(Deliverables!$B$2:$B$563,A4,Deliverables!$I$2:$I$563,"<>Approved / IFI",Deliverables!$H$2:$H$563,"<"&Config!$B$2) -> 2 | W4: =COUNTIFS(Risks!$B$2:$B$35,A4,Risks!$K$2:$K$35,"Open") -> 2 | X4: =COUNTIF(Allocations!$C$2:$C$73,A4) -> 5 | Y4: =IF(T4=0,0,ROUND(U4/T4*100,0)) -> 47 | Z4: 0 | AA4: Pending | AB4: Process debottlenecking of the produced water treatment train to meet revised discharge and reinjection specifications. | AC4: =A4&" - "&B4 -> PRJ-018 - Produced Water Upgrade | AD4: =HYPERLINK(Config!$B$3&"/"&AC4,"Open project folder") -> Open project folder | AE4: =Config!$B$3&"/"&AC4 -> PASTE-YOUR-ONEDRIVE-PROJECT-FILES-FOLDER-URL-HERE/PRJ-018 - Produced Water Upgrade
A5: PRJ-015 | B5: Gas Export Metering | C5: Metering package | D5: OML 10 | E5: Engineering | F5: Contractor-led | G5: Asset Project | H5: Define | I5: =IF(J5="Closeout","Closeout / Archive",IF(H5="Define","Define",IF(H5="Execute","Execute","Concept / Assess"))) -> Define | J5: Active | K5: M. Bello | L5: S. Aliyu | M5: 58 | N5: 52 | O5: 12 | P5: Red | Q5: 45915 | R5: 46310 | S5: 46327 | T5: =COUNTIF(Deliverables!$B$2:$B$563,A5) -> 18 | U5: =COUNTIFS(Deliverables!$B$2:$B$563,A5,Deliverables!$I$2:$I$563,"Approved / IFI") -> 11 | V5: =COUNTIFS(Deliverables!$B$2:$B$563,A5,Deliverables!$I$2:$I$563,"<>Approved / IFI",Deliverables!$H$2:$H$563,"<"&Config!$B$2) -> 3 | W5: =COUNTIFS(Risks!$B$2:$B$35,A5,Risks!$K$2:$K$35,"Open") -> 1 | X5: =COUNTIF(Allocations!$C$2:$C$73,A5) -> 2 | Y5: =IF(T5=0,0,ROUND(U5/T5*100,0)) -> 61 | Z5: 0 | AA5: Pending | AB5: Replacement metering package for gas export fiscal measurement, including new metering skid, prover loop and control system integration. | AC5: =A5&" - "&B5 -> PRJ-015 - Gas Export Metering | AD5: =HYPERLINK(Config!$B$3&"/"&AC5,"Open project folder") -> Open project folder | AE5: =Config!$B$3&"/"&AC5 -> PASTE-YOUR-ONEDRIVE-PROJECT-FILES-FOLDER-URL-HERE/PRJ-015 - Gas Export Metering
A6: PRJ-011 | B6: Utilities Reliability | C6: Utilities upgrade | D6: OML 1 | E6: Project Execution | F6: In-house | G6: Asset Project | H6: Execute | I6: =IF(J6="Closeout","Closeout / Archive",IF(H6="Define","Define",IF(H6="Execute","Execute","Concept / Assess"))) -> Execute | J6: Active | K6: R. Bello | L6: D. Umeh | M6: 84 | N6: 86 | O6: -2 | P6: Green | Q6: 45826 | R6: 46283 | S6: 46281 | T6: =COUNTIF(Deliverables!$B$2:$B$563,A6) -> 17 | U6: =COUNTIFS(Deliverables!$B$2:$B$563,A6,Deliverables!$I$2:$I$563,"Approved / IFI") -> 16 | V6: =COUNTIFS(Deliverables!$B$2:$B$563,A6,Deliverables!$I$2:$I$563,"<>Approved / IFI",Deliverables!$H$2:$H$563,"<"&Config!$B$2) -> 0 | W6: =COUNTIFS(Risks!$B$2:$B$35,A6,Risks!$K$2:$K$35,"Open") -> 0 | X6: =COUNTIF(Allocations!$C$2:$C$73,A6) -> 0 | Y6: =IF(T6=0,0,ROUND(U6/T6*100,0)) -> 94 | Z6: 0 | AA6: Pending | AB6: Reliability improvement programme across instrument air, power generation and cooling water utility systems. | AC6: =A6&" - "&B6 -> PRJ-011 - Utilities Reliability | AD6: =HYPERLINK(Config!$B$3&"/"&AC6,"Open project folder") -> Open project folder | AE6: =Config!$B$3&"/"&AC6 -> PASTE-YOUR-ONEDRIVE-PROJECT-FILES-FOLDER-URL-HERE/PRJ-011 - Utilities Reliability
A7: GLB-003 | B7: Licence Validation Programme | C7: Cross-asset licence compliance | D7: Global | E7: CRV | F7: In-house | G7: Global Initiative | H7: Assess | I7: =IF(J7="Closeout","Closeout / Archive",IF(H7="Define","Define",IF(H7="Execute","Execute","Concept / Assess"))) -> Concept / Assess | J7: Active | K7: K. Briggs | L7: H. Sanni | M7: 45 | N7: 43 | O7: 0 | P7: Amber | Q7: 46174 | R7: 46447 | S7: 46461 | T7: =COUNTIF(Deliverables!$B$2:$B$563,A7) -> 20 | U7: =COUNTIFS(Deliverables!$B$2:$B$563,A7,Deliverables!$I$2:$I$563,"Approved / IFI") -> 7 | V7: =COUNTIFS(Deliverables!$B$2:$B$563,A7,Deliverables!$I$2:$I$563,"<>Approved / IFI",Deliverables!$H$2:$H$563,"<"&Config!$B$2) -> 2 | W7: =COUNTIFS(Risks!$B$2:$B$35,A7,Risks!$K$2:$K$35,"Open") -> 0 | X7: =COUNTIF(Allocations!$C$2:$C$73,A7) -> 1 | Y7: =IF(T7=0,0,ROUND(U7/T7*100,0)) -> 35 | Z7: 0 | AA7: Pending | AB7: Cross-asset programme validating licence-to-operate documentation and regulatory compliance evidence across all producing assets. | AC7: =A7&" - "&B7 -> GLB-003 - Licence Validation Programme | AD7: =HYPERLINK(Config!$B$3&"/"&AC7,"Open project folder") -> Open project folder | AE7: =Config!$B$3&"/"&AC7 -> PASTE-YOUR-ONEDRIVE-PROJECT-FILES-FOLDER-URL-HERE/GLB-003 - Licence Validation Programme
A8: PRJ-006 | B8: Utility Tie-In | C8: Utility interconnection | D8: OML 1 | E8: Project Execution | F8: In-house | G8: Asset Project | H8: Operate | I8: =IF(J8="Closeout","Closeout / Archive",IF(H8="Define","Define",IF(H8="Execute","Execute","Concept / Assess"))) -> Closeout / Archive | J8: Closeout | K8: R. Bello | L8: D. Umeh | M8: 100 | N8: 100 | O8: 0 | P8: Amber | Q8: 45687 | R8: 46203 | S8: 46208 | T8: =COUNTIF(Deliverables!$B$2:$B$563,A8) -> 16 | U8: =COUNTIFS(Deliverables!$B$2:$B$563,A8,Deliverables!$I$2:$I$563,"Approved / IFI") -> 15 | V8: =COUNTIFS(Deliverables!$B$2:$B$563,A8,Deliverables!$I$2:$I$563,"<>Approved / IFI",Deliverables!$H$2:$H$563,"<"&Config!$B$2) -> 0 | W8: =COUNTIFS(Risks!$B$2:$B$35,A8,Risks!$K$2:$K$35,"Open") -> 0 | X8: =COUNTIF(Allocations!$C$2:$C$73,A8) -> 0 | Y8: =IF(T8=0,0,ROUND(U8/T8*100,0)) -> 94 | Z8: 3 | AA8: Pending | AB8: Tie-in of new utility interconnection between the central processing facility and satellite flowstation. | AC8: =A8&" - "&B8 -> PRJ-006 - Utility Tie-In | AD8: =HYPERLINK(Config!$B$3&"/"&AC8,"Open project folder") -> Open project folder | AE8: =Config!$B$3&"/"&AC8 -> PASTE-YOUR-ONEDRIVE-PROJECT-FILES-FOLDER-URL-HERE/PRJ-006 - Utility Tie-In
A9: PRJ-009 | B9: Compressor Reliability | C9: Reliability upgrade | D9: OML 4 | E9: Engineering | F9: In-house | G9: Asset Project | H9: Operate | I9: =IF(J9="Closeout","Closeout / Archive",IF(H9="Define","Define",IF(H9="Execute","Execute","Concept / Assess"))) -> Closeout / Archive | J9: Closeout | K9: O. Adeyemi | L9: A. Musa | M9: 100 | N9: 100 | O9: 0 | P9: Green | Q9: 45555 | R9: 46162 | S9: 46160 | T9: =COUNTIF(Deliverables!$B$2:$B$563,A9) -> 19 | U9: =COUNTIFS(Deliverables!$B$2:$B$563,A9,Deliverables!$I$2:$I$563,"Approved / IFI") -> 18 | V9: =COUNTIFS(Deliverables!$B$2:$B$563,A9,Deliverables!$I$2:$I$563,"<>Approved / IFI",Deliverables!$H$2:$H$563,"<"&Config!$B$2) -> 0 | W9: =COUNTIFS(Risks!$B$2:$B$35,A9,Risks!$K$2:$K$35,"Open") -> 0 | X9: =COUNTIF(Allocations!$C$2:$C$73,A9) -> 0 | Y9: =IF(T9=0,0,ROUND(U9/T9*100,0)) -> 95 | Z9: 0 | AA9: Complete | AB9: Reliability upgrade of export compressor auxiliaries following repeated trip events. | AC9: =A9&" - "&B9 -> PRJ-009 - Compressor Reliability | AD9: =HYPERLINK(Config!$B$3&"/"&AC9,"Open project folder") -> Open project folder | AE9: =Config!$B$3&"/"&AC9 -> PASTE-YOUR-ONEDRIVE-PROJECT-FILES-FOLDER-URL-HERE/PRJ-009 - Compressor Reliability
A10: PRJ-005 | B10: Separator Debottleneck Study | C10: Concept study | D10: OML 3 | E10: Engineering | F10: In-house | G10: Asset Project | H10: Assess | I10: =IF(J10="Closeout","Closeout / Archive",IF(H10="Define","Define",IF(H10="Execute","Execute","Concept / Assess"))) -> Concept / Assess | J10: Active | K10: F. Nwosu | L10: I. Ogundele | M10: 32 | N10: 28 | O10: 3 | P10: Green | Q10: 46122 | R10: 46397 | S10: 46402 | T10: =COUNTIF(Deliverables!$B$2:$B$563,A10) -> 11 | U10: =COUNTIFS(Deliverables!$B$2:$B$563,A10,Deliverables!$I$2:$I$563,"Approved / IFI") -> 3 | V10: =COUNTIFS(Deliverables!$B$2:$B$563,A10,Deliverables!$I$2:$I$563,"<>Approved / IFI",Deliverables!$H$2:$H$563,"<"&Config!$B$2) -> 4 | W10: =COUNTIFS(Risks!$B$2:$B$35,A10,Risks!$K$2:$K$35,"Open") -> 1 | X10: =COUNTIF(Allocations!$C$2:$C$73,A10) -> 3 | Y10: =IF(T10=0,0,ROUND(U10/T10*100,0)) -> 27 | Z10: 0 | AA10: Pending | AB10: Concept-level study to debottleneck the second-stage separator train ahead of planned production ramp-up. | AC10: =A10&" - "&B10 -> PRJ-005 - Separator Debottleneck Study | AD10: =HYPERLINK(Config!$B$3&"/"&AC10,"Open project folder") -> Open project folder | AE10: =Config!$B$3&"/"&AC10 -> PASTE-YOUR-ONEDRIVE-PROJECT-FILES-FOLDER-URL-HERE/PRJ-005 - Separator Debottleneck Study
A11: PRJ-008 | B11: Flare System Upgrade | C11: Concept study | D11: OML 4 | E11: Engineering | F11: In-house | G11: Asset Project | H11: Assess | I11: =IF(J11="Closeout","Closeout / Archive",IF(H11="Define","Define",IF(H11="Execute","Execute","Concept / Assess"))) -> Concept / Assess | J11: Active | K11: N. Balogun | L11: A. Musa | M11: 28 | N11: 22 | O11: 5 | P11: Amber | Q11: 46147 | R11: 46423 | S11: 46432 | T11: =COUNTIF(Deliverables!$B$2:$B$563,A11) -> 13 | U11: =COUNTIFS(Deliverables!$B$2:$B$563,A11,Deliverables!$I$2:$I$563,"Approved / IFI") -> 2 | V11: =COUNTIFS(Deliverables!$B$2:$B$563,A11,Deliverables!$I$2:$I$563,"<>Approved / IFI",Deliverables!$H$2:$H$563,"<"&Config!$B$2) -> 3 | W11: =COUNTIFS(Risks!$B$2:$B$35,A11,Risks!$K$2:$K$35,"Open") -> 1 | X11: =COUNTIF(Allocations!$C$2:$C$73,A11) -> 3 | Y11: =IF(T11=0,0,ROUND(U11/T11*100,0)) -> 15 | Z11: 0 | AA11: Pending | AB11: Assessment of flare tip and knockout drum capacity against revised process design basis. | AC11: =A11&" - "&B11 -> PRJ-008 - Flare System Upgrade | AD11: =HYPERLINK(Config!$B$3&"/"&AC11,"Open project folder") -> Open project folder | AE11: =Config!$B$3&"/"&AC11 -> PASTE-YOUR-ONEDRIVE-PROJECT-FILES-FOLDER-URL-HERE/PRJ-008 - Flare System Upgrade
A12: PRJ-013 | B12: Wellhead Platform Modification | C12: Concept select | D12: OML 5 | E12: Engineering | F12: Hybrid | G12: Asset Project | H12: Select | I12: =IF(J12="Closeout","Closeout / Archive",IF(H12="Define","Define",IF(H12="Execute","Execute","Concept / Assess"))) -> Concept / Assess | J12: Active | K12: C. Danjuma | L12: T. Ogundele | M12: 40 | N12: 36 | O12: 4 | P12: Green | Q12: 46132 | R12: 46376 | S12: 46384 | T12: =COUNTIF(Deliverables!$B$2:$B$563,A12) -> 16 | U12: =COUNTIFS(Deliverables!$B$2:$B$563,A12,Deliverables!$I$2:$I$563,"Approved / IFI") -> 4 | V12: =COUNTIFS(Deliverables!$B$2:$B$563,A12,Deliverables!$I$2:$I$563,"<>Approved / IFI",Deliverables!$H$2:$H$563,"<"&Config!$B$2) -> 2 | W12: =COUNTIFS(Risks!$B$2:$B$35,A12,Risks!$K$2:$K$35,"Open") -> 0 | X12: =COUNTIF(Allocations!$C$2:$C$73,A12) -> 6 | Y12: =IF(T12=0,0,ROUND(U12/T12*100,0)) -> 25 | Z12: 0 | AA12: Pending | AB12: Selection of preferred concept for wellhead platform modification to accommodate two additional well slots. | AC12: =A12&" - "&B12 -> PRJ-013 - Wellhead Platform Modification | AD12: =HYPERLINK(Config!$B$3&"/"&AC12,"Open project folder") -> Open project folder | AE12: =Config!$B$3&"/"&AC12 -> PASTE-YOUR-ONEDRIVE-PROJECT-FILES-FOLDER-URL-HERE/PRJ-013 - Wellhead Platform Modification
A13: PRJ-019 | B13: Corrosion Management Programme | C13: Identify | D13: OML 7 | E13: Engineering | F13: In-house | G13: Asset Project | H13: Identify | I13: =IF(J13="Closeout","Closeout / Archive",IF(H13="Define","Define",IF(H13="Execute","Execute","Concept / Assess"))) -> Concept / Assess | J13: Active | K13: L. Abubakar | L13: F. Etim | M13: 14 | N13: 11 | O13: 2 | P13: Green | Q13: 46357 | R13: 46478 | S13: 46485 | T13: =COUNTIF(Deliverables!$B$2:$B$563,A13) -> 8 | U13: =COUNTIFS(Deliverables!$B$2:$B$563,A13,Deliverables!$I$2:$I$563,"Approved / IFI") -> 1 | V13: =COUNTIFS(Deliverables!$B$2:$B$563,A13,Deliverables!$I$2:$I$563,"<>Approved / IFI",Deliverables!$H$2:$H$563,"<"&Config!$B$2) -> 1 | W13: =COUNTIFS(Risks!$B$2:$B$35,A13,Risks!$K$2:$K$35,"Open") -> 1 | X13: =COUNTIF(Allocations!$C$2:$C$73,A13) -> 1 | Y13: =IF(T13=0,0,ROUND(U13/T13*100,0)) -> 13 | Z13: 0 | AA13: Pending | AB13: Identification phase for an integrity programme addressing internal corrosion on ageing flowline network. | AC13: =A13&" - "&B13 -> PRJ-019 - Corrosion Management Programme | AD13: =HYPERLINK(Config!$B$3&"/"&AC13,"Open project folder") -> Open project folder | AE13: =Config!$B$3&"/"&AC13 -> PASTE-YOUR-ONEDRIVE-PROJECT-FILES-FOLDER-URL-HERE/PRJ-019 - Corrosion Management Programme
... A32: GLB-002 | B32: Emergency Response Plan Update | C32: Closeout | D32: Global | E32: CRV | F32: In-house | G32: Global Initiative | H32: Operate | I32: =IF(J32="Closeout","Closeout / Archive",IF(H32="Define","Define",IF(H32="Execute","Execute","Concept / Assess"))) -> Closeout / Archive | J32: Closeout | K32: K. Briggs | L32: H. Sanni | M32: 100 | N32: 100 | O32: 0 | P32: Amber | Q32: 45616 | R32: 46101 | S32: 46106 | T32: =COUNTIF(Deliverables!$B$2:$B$563,A32) -> 19 | U32: =COUNTIFS(Deliverables!$B$2:$B$563,A32,Deliverables!$I$2:$I$563,"Approved / IFI") -> 18 | V32: =COUNTIFS(Deliverables!$B$2:$B$563,A32,Deliverables!$I$2:$I$563,"<>Approved / IFI",Deliverables!$H$2:$H$563,"<"&Config!$B$2) -> 0 | W32: =COUNTIFS(Risks!$B$2:$B$35,A32,Risks!$K$2:$K$35,"Open") -> 0 | X32: =COUNTIF(Allocations!$C$2:$C$73,A32) -> 0 | Y32: =IF(T32=0,0,ROUND(U32/T32*100,0)) -> 95 | Z32: 2 | AA32: Pending | AB32: Cross-asset update of emergency response plans and drills, pending final sign-off. | AC32: =A32&" - "&B32 -> GLB-002 - Emergency Response Plan Update | AD32: =HYPERLINK(Config!$B$3&"/"&AC32,"Open project folder") -> Open project folder | AE32: =Config!$B$3&"/"&AC32 -> PASTE-YOUR-ONEDRIVE-PROJECT-FILES-FOLDER-URL-HERE/GLB-002 - Emergency Response Plan Update

Sheet People
A1: PersonID | B1: Name | C1: Discipline | D1: Department | E1: CapacityFTE | F1: PrimaryAsset | G1: AllocatedPct | H1: UtilisationStatus
A2: P-001 | B2: A. Musa | C2: Process | D2: Engineering | E2: 1 | F2: OML 4 | G2: =SUMIFS(Allocations!$D$2:$D$73,Allocations!$B$2:$B$73,A2) -> 84 | H2: =IF(G2>105,"Overloaded",IF(G2>=95,"High",IF(G2>=70,"Healthy","Available"))) -> Healthy
A3: P-002 | B3: G. Chukwu | C3: Process | D3: Engineering | E3: 1 | F3: OML 2 | G3: =SUMIFS(Allocations!$D$2:$D$73,Allocations!$B$2:$B$73,A3) -> 106 | H3: =IF(G3>105,"Overloaded",IF(G3>=95,"High",IF(G3>=70,"Healthy","Available"))) -> Overloaded
A4: P-003 | B4: S. Aliyu | C4: Process | D4: Engineering | E4: 1 | F4: OML 10 | G4: =SUMIFS(Allocations!$D$2:$D$73,Allocations!$B$2:$B$73,A4) -> 112 | H4: =IF(G4>105,"Overloaded",IF(G4>=95,"High",IF(G4>=70,"Healthy","Available"))) -> Overloaded
A5: P-004 | B5: D. Umeh | C5: Mechanical | D5: Engineering | E5: 1 | F5: OML 1 | G5: =SUMIFS(Allocations!$D$2:$D$73,Allocations!$B$2:$B$73,A5) -> 113 | H5: =IF(G5>105,"Overloaded",IF(G5>=95,"High",IF(G5>=70,"Healthy","Available"))) -> Overloaded
A6: P-005 | B6: B. Yusuf | C6: Mechanical | D6: Engineering | E6: 1 | F6: OML 4 | G6: =SUMIFS(Allocations!$D$2:$D$73,Allocations!$B$2:$B$73,A6) -> 63 | H6: =IF(G6>105,"Overloaded",IF(G6>=95,"High",IF(G6>=70,"Healthy","Available"))) -> Available
A7: P-006 | B7: B. Okafor | C7: Mechanical | D7: Engineering | E7: 1 | F7: OML 4 | G7: =SUMIFS(Allocations!$D$2:$D$73,Allocations!$B$2:$B$73,A7) -> 96 | H7: =IF(G7>105,"Overloaded",IF(G7>=95,"High",IF(G7>=70,"Healthy","Available"))) -> High
A8: P-007 | B8: I. Ogundele | C8: Piping | D8: Engineering | E8: 1 | F8: OML 3 | G8: =SUMIFS(Allocations!$D$2:$D$73,Allocations!$B$2:$B$73,A8) -> 59 | H8: =IF(G8>105,"Overloaded",IF(G8>=95,"High",IF(G8>=70,"Healthy","Available"))) -> Available
A9: P-008 | B9: E. Okoro | C9: Piping | D9: Engineering | E9: 1 | F9: OML 2 | G9: =SUMIFS(Allocations!$D$2:$D$73,Allocations!$B$2:$B$73,A9) -> 61 | H9: =IF(G9>105,"Overloaded",IF(G9>=95,"High",IF(G9>=70,"Healthy","Available"))) -> Available
A10: P-009 | B10: H. Sanni | C10: Instrumentation | D10: Engineering | E10: 1 | F10: Global | G10: =SUMIFS(Allocations!$D$2:$D$73,Allocations!$B$2:$B$73,A10) -> 50 | H10: =IF(G10>105,"Overloaded",IF(G10>=95,"High",IF(G10>=70,"Healthy","Available"))) -> Available
A11: P-010 | B11: F. Etim | C11: Electrical | D11: Engineering | E11: 1 | F11: OML 7 | G11: =SUMIFS(Allocations!$D$2:$D$73,Allocations!$B$2:$B$73,A11) -> 51 | H11: =IF(G11>105,"Overloaded",IF(G11>=95,"High",IF(G11>=70,"Healthy","Available"))) -> Available
A12: P-011 | B12: M. Ekong | C12: Electrical | D12: Engineering | E12: 1 | F12: OML 9 | G12: =SUMIFS(Allocations!$D$2:$D$73,Allocations!$B$2:$B$73,A12) -> 47 | H12: =IF(G12>105,"Overloaded",IF(G12>=95,"High",IF(G12>=70,"Healthy","Available"))) -> Available
A13: P-012 | B13: C. James | C13: Electrical | D13: Engineering | E13: 1 | F13: OML 7 | G13: =SUMIFS(Allocations!$D$2:$D$73,Allocations!$B$2:$B$73,A13) -> 112 | H13: =IF(G13>105,"Overloaded",IF(G13>=95,"High",IF(G13>=70,"Healthy","Available"))) -> Overloaded
... A53: P-052 | B53: H. Yusuf | C53: Project Controls | D53: Project Services | E53: 1 | F53: OML 1 | G53: =SUMIFS(Allocations!$D$2:$D$73,Allocations!$B$2:$B$73,A53) -> 95 | H53: =IF(G53>105,"Overloaded",IF(G53>=95,"High",IF(G53>=70,"Healthy","Available"))) -> High

Sheet Allocations
A1: AllocationID | B1: PersonID | C1: ProjectID | D1: AllocationPct | E1: RoleOnProject
A2: AL-001 | B2: P-012 | C2: PRJ-021 | D2: 65 | E2: Electrical Engineer
A3: AL-002 | B3: P-012 | C3: PRJ-024 | D3: 47 | E3: Electrical Engineer
A4: AL-003 | B4: P-006 | C4: PRJ-024 | D4: 55 | E4: Mechanical Engineer
A5: AL-004 | B5: P-006 | C5: PRJ-018 | D5: 41 | E5: Mechanical Engineer
A6: AL-005 | B6: P-001 | C6: PRJ-024 | D6: 50 | E6: Lead Process Engineer
A7: AL-006 | B7: P-001 | C7: PRJ-015 | D7: 34 | E7: Process Engineer
A8: AL-007 | B8: P-008 | C8: PRJ-018 | D8: 61 | E8: Piping Engineer
A9: AL-008 | B9: P-002 | C9: PRJ-003 | D9: 65 | E9: Process Engineer
A10: AL-009 | B10: P-002 | C10: PRJ-018 | D10: 41 | E10: Process Engineer
A11: AL-010 | B11: P-003 | C11: PRJ-023 | D11: 72 | E11: Process Engineer
A12: AL-011 | B12: P-003 | C12: PRJ-026 | D12: 40 | E12: Process Engineer
A13: AL-012 | B13: P-004 | C13: PRJ-001 | D13: 113 | E13: Mechanical Engineer
... A73: AL-072 | B73: P-052 | C73: PRJ-004 | D73: 47 | E73: Project Controls Lead

Sheet Deliverables
A1: DeliverableID | B1: ProjectID | C1: DeliverableName | D1: Discipline | E1: ResponsiblePerson | F1: Revision | G1: IssueDate | H1: DueDate | I1: WorkflowStatus | J1: IsOverdue | K1: DisplayStatus
A2: MDR-0001 | B2: PRJ-024 | C2: Rotating Equipment Spec | D2: Mechanical | E2: B. Okafor | F2: 1 | G2: 46064 | H2: 46082 | I2: Approved / IFI | J2: =IF(AND(H2<Config!$B$2,I2<>"Approved / IFI"),TRUE,FALSE) -> FALSE | K2: =IF(J2=TRUE,"Overdue",IF(I2="Approved / IFI","Complete",IF(I2="Internal Development","In Progress",IF(I2="Revise & Resubmit","Revise","In Review")))) -> Complete
A3: MDR-0002 | B3: PRJ-024 | C3: Vessel Mechanical Design | D3: Mechanical | E3: Q. Chukwu | F3: 2 | G3: 46080 | H3: 46116 | I3: Approved / IFI | J3: =IF(AND(H3<Config!$B$2,I3<>"Approved / IFI"),TRUE,FALSE) -> FALSE | K3: =IF(J3=TRUE,"Overdue",IF(I3="Approved / IFI","Complete",IF(I3="Internal Development","In Progress",IF(I3="Revise & Resubmit","Revise","In Review")))) -> Complete
A4: MDR-0003 | B4: PRJ-024 | C4: Tie-in Schedule | D4: Piping | E4: I. Ogundele | F4: 3 | G4: 46121 | H4: 46140 | I4: Approved / IFI | J4: =IF(AND(H4<Config!$B$2,I4<>"Approved / IFI"),TRUE,FALSE) -> FALSE | K4: =IF(J4=TRUE,"Overdue",IF(I4="Approved / IFI","Complete",IF(I4="Internal Development","In Progress",IF(I4="Revise & Resubmit","Revise","In Review")))) -> Complete
A5: MDR-0004 | B5: PRJ-024 | C5: Cause & Effect Diagram - OML 4 | D5: Instrumentation | E5: S. Uzoma | F5: 1 | G5: 46085 | H5: 46108 | I5: Approved / IFI | J5: =IF(AND(H5<Config!$B$2,I5<>"Approved / IFI"),TRUE,FALSE) -> FALSE | K5: =IF(J5=TRUE,"Overdue",IF(I5="Approved / IFI","Complete",IF(I5="Internal Development","In Progress",IF(I5="Revise & Resubmit","Revise","In Review")))) -> Complete
A6: MDR-0005 | B6: PRJ-024 | C6: Line List | D6: Piping | E6: U. Chukwuemeka | F6: 3 | G6: 46071 | H6: 46086 | I6: Approved / IFI | J6: =IF(AND(H6<Config!$B$2,I6<>"Approved / IFI"),TRUE,FALSE) -> FALSE | K6: =IF(J6=TRUE,"Overdue",IF(I6="Approved / IFI","Complete",IF(I6="Internal Development","In Progress",IF(I6="Revise & Resubmit","Revise","In Review")))) -> Complete
A7: MDR-0006 | B7: PRJ-024 | C7: Compressor Datasheet - OML 4 | D7: Mechanical | E7: B. Okafor | F7: 3 | G7: 46166 | H7: 46189 | I7: Approved / IFI | J7: =IF(AND(H7<Config!$B$2,I7<>"Approved / IFI"),TRUE,FALSE) -> FALSE | K7: =IF(J7=TRUE,"Overdue",IF(I7="Approved / IFI","Complete",IF(I7="Internal Development","In Progress",IF(I7="Revise & Resubmit","Revise","In Review")))) -> Complete
A8: MDR-0007 | B8: PRJ-024 | C8: Corrosion Assessment Report - OML 4 | D8: Pipeline | E8: C. Ibrahim | F8: 4 | G8: 46068 | H8: 46083 | I8: Approved / IFI | J8: =IF(AND(H8<Config!$B$2,I8<>"Approved / IFI"),TRUE,FALSE) -> FALSE | K8: =IF(J8=TRUE,"Overdue",IF(I8="Approved / IFI","Complete",IF(I8="Internal Development","In Progress",IF(I8="Revise & Resubmit","Revise","In Review")))) -> Complete
A9: MDR-0008 | B9: PRJ-024 | C9: Electrical Design Basis | D9: Electrical | E9: M. Ekong | F9: 4 | G9: 46147 | H9: 46186 | I9: Approved / IFI | J9: =IF(AND(H9<Config!$B$2,I9<>"Approved / IFI"),TRUE,FALSE) -> FALSE | K9: =IF(J9=TRUE,"Overdue",IF(I9="Approved / IFI","Complete",IF(I9="Internal Development","In Progress",IF(I9="Revise & Resubmit","Revise","In Review")))) -> Complete
A10: MDR-0009 | B10: PRJ-024 | C10: Pipe Support Register - OML 4 | D10: Piping | E10: U. Chukwuemeka | F10: 4 | G10: 46169 | H10: 46200 | I10: Approved / IFI | J10: =IF(AND(H10<Config!$B$2,I10<>"Approved / IFI"),TRUE,FALSE) -> FALSE | K10: =IF(J10=TRUE,"Overdue",IF(I10="Approved / IFI","Complete",IF(I10="Internal Development","In Progress",IF(I10="Revise & Resubmit","Revise","In Review")))) -> Complete
A11: MDR-0010 | B11: PRJ-024 | C11: Instrument Index | D11: Instrumentation | E11: S. Aliyu | F11: 1 | G11: 46197 | H11: 46226 | I11: Approved / IFI | J11: =IF(AND(H11<Config!$B$2,I11<>"Approved / IFI"),TRUE,FALSE) -> FALSE | K11: =IF(J11=TRUE,"Overdue",IF(I11="Approved / IFI","Complete",IF(I11="Internal Development","In Progress",IF(I11="Revise & Resubmit","Revise","In Review")))) -> Complete
A12: MDR-0011 | B12: PRJ-024 | C12: SCADA Architecture Drawing - OML 4 | D12: Instrumentation | E12: I. Briggs | F12: 1 | G12: 46188 | H12: 46212 | I12: Approved / IFI | J12: =IF(AND(H12<Config!$B$2,I12<>"Approved / IFI"),TRUE,FALSE) -> FALSE | K12: =IF(J12=TRUE,"Overdue",IF(I12="Approved / IFI","Complete",IF(I12="Internal Development","In Progress",IF(I12="Revise & Resubmit","Revise","In Review")))) -> Complete
A13: MDR-0012 | B13: PRJ-024 | C13: Mechanical Handling Study | D13: Mechanical | E13: B. Okafor | F13: 0 | G13: 46124 | H13: 46159 | I13: Approved / IFI | J13: =IF(AND(H13<Config!$B$2,I13<>"Approved / IFI"),TRUE,FALSE) -> FALSE | K13: =IF(J13=TRUE,"Overdue",IF(I13="Approved / IFI","Complete",IF(I13="Internal Development","In Progress",IF(I13="Revise & Resubmit","Revise","In Review")))) -> Complete
... A563: MDR-0562 | B563: GLB-002 | C563: Line List | D563: Piping | E563: P. Ndukwe | F563: 3 | G563: 46234 | H563: 46256 | I563: Internal Development | J563: =IF(AND(H563<Config!$B$2,I563<>"Approved / IFI"),TRUE,FALSE) -> FALSE | K563: =IF(J563=TRUE,"Overdue",IF(I563="Approved / IFI","Complete",IF(I563="Internal Development","In Progress",IF(I563="Revise & Resubmit","Revise","In Review")))) -> In Progress

Sheet Risks
A1: RiskID | B1: ProjectID | C1: RiskDescription | D1: Category | E1: Likelihood | F1: Impact | G1: Score | H1: RiskLevel | I1: Owner | J1: MitigationAction | K1: Status | L1: RaisedDate | M1: TargetCloseDate
A2: RSK-001 | B2: PRJ-024 | C2: Electrical engineering capacity constrained against concurrent project demand | D2: Schedule | E2: 4 | F2: 4 | G2: =E2*F2 -> 16 | H2: =IF(G2>=15,"High",IF(G2>=8,"Medium","Low")) -> High | I2: Eng. Manager | J2: Rebalance workload | K2: Open | L2: 46231 | M2: 46270
A3: RSK-002 | B3: PRJ-024 | C3: Long-lead compressor vendor data delayed against design programme | D3: Schedule / Cost | E3: 5 | F3: 3 | G3: =E3*F3 -> 15 | H3: =IF(G3>=15,"High",IF(G3>=8,"Medium","Low")) -> High | I3: Mechanical Lead | J3: Expedite vendor | K3: Open | L3: 46224 | M3: 46290
A4: RSK-003 | B4: PRJ-021 | C4: Brownfield access window constrained by production shutdown schedule | D4: Execution | E4: 4 | F4: 3 | G4: =E4*F4 -> 12 | H4: =IF(G4>=15,"High",IF(G4>=8,"Medium","Low")) -> Medium | I4: Execution Lead | J4: Confirm shutdown plan | K4: Open | L4: 46237 | M4: 46320
A5: RSK-004 | B5: PRJ-022 | C5: Contractor productivity below plan | D5: Schedule | E5: 4 | F5: 2 | G5: =E5*F5 -> 8 | H5: =IF(G5>=15,"High",IF(G5>=8,"Medium","Low")) -> Medium | I5: Execution Lead | J5: Under review by project team | K5: Open | L5: 46218 | M5: 46246
A6: RSK-005 | B6: PRJ-024 | C6: Site access / permitting delay risk | D6: Commercial | E6: 5 | F6: 5 | G6: =E6*F6 -> 25 | H6: =IF(G6>=15,"High",IF(G6>=8,"Medium","Low")) -> High | I6: Discipline Lead | J6: Under review by project team | K6: Open | L6: 46244 | M6: 46288
A7: RSK-006 | B7: PRJ-020 | C7: Third-party interface dependency | D7: Commercial | E7: 2 | F7: 3 | G7: =E7*F7 -> 6 | H7: =IF(G7>=15,"High",IF(G7>=8,"Medium","Low")) -> Low | I7: Project Manager | J7: Under review by project team | K7: Open | L7: 46211 | M7: 46294
A8: RSK-007 | B8: PRJ-024 | C8: Design change from HAZOP / HAZID action | D8: Execution | E8: 3 | F8: 3 | G8: =E8*F8 -> 9 | H8: =IF(G8>=15,"High",IF(G8>=8,"Medium","Low")) -> Medium | I8: Discipline Lead | J8: Under review by project team | K8: Open | L8: 46219 | M8: 46258
A9: RSK-008 | B9: PRJ-008 | C9: Interface misalignment between engineering and construction | D9: Cost | E9: 5 | F9: 3 | G9: =E9*F9 -> 15 | H9: =IF(G9>=15,"High",IF(G9>=8,"Medium","Low")) -> High | I9: Project Manager | J9: Under review by project team | K9: Open | L9: 46237 | M9: 46270
A10: RSK-009 | B10: PRJ-003 | C10: Budget contingency erosion risk | D10: Technical | E10: 2 | F10: 3 | G10: =E10*F10 -> 6 | H10: =IF(G10>=15,"High",IF(G10>=8,"Medium","Low")) -> Low | I10: Project Manager | J10: Under review by project team | K10: Open | L10: 46209 | M10: 46287
A11: RSK-010 | B11: GLB-005 | C11: Key resource attrition risk on critical path discipline | D11: Technical | E11: 3 | F11: 3 | G11: =E11*F11 -> 9 | H11: =IF(G11>=15,"High",IF(G11>=8,"Medium","Low")) -> Medium | I11: Eng. Manager | J11: Under review by project team | K11: Open | L11: 46232 | M11: 46283
A12: RSK-011 | B12: PRJ-023 | C12: Regulatory approval timeline uncertainty | D12: Safety | E12: 4 | F12: 4 | G12: =E12*F12 -> 16 | H12: =IF(G12>=15,"High",IF(G12>=8,"Medium","Low")) -> High | I12: Execution Lead | J12: Under review by project team | K12: Open | L12: 46197 | M12: 46256
A13: RSK-012 | B13: PRJ-016 | C13: Site access / permitting delay risk | D13: Cost | E13: 5 | F13: 5 | G13: =E13*F13 -> 25 | H13: =IF(G13>=15,"High",IF(G13>=8,"Medium","Low")) -> High | I13: Execution Lead | J13: Under review by project team | K13: Open | L13: 46236 | M13: 46287
... A35: RSK-034 | B35: PRJ-026 | C35: Third-party interface dependency | D35: Schedule | E35: 2 | F35: 3 | G35: =E35*F35 -> 6 | H35: =IF(G35>=15,"High",IF(G35>=8,"Medium","Low")) -> Low | I35: Eng. Manager | J35: Mitigated and closed out | K35: Closed | L35: 46051 | M35: 46119

Sheet Issues
A1: IssueID | B1: ProjectID | C1: IssueDescription | D1: Severity | E1: Owner | F1: RaisedDate | G1: Status | H1: TargetCloseDate
A2: ISS-001 | B2: PRJ-018 | C2: Field query awaiting engineering response | D2: Medium | E2: Discipline Lead | F2: 46227 | G2: Open | H2: 46252
A3: ISS-002 | B3: PRJ-012 | C3: Non-conformance report open against fabrication | D3: Medium | E3: Eng. Manager | F3: 46218 | G3: Open | H3: 46243
A4: ISS-003 | B4: PRJ-018 | C4: As-built discrepancy against design drawing | D4: Low | E4: Eng. Manager | F4: 46196 | G4: Open | H4: 46232
A5: ISS-004 | B5: PRJ-003 | C5: Vendor document non-conformance | D5: Medium | E5: Discipline Lead | F5: 46233 | G5: Open | H5: 46249
A6: ISS-005 | B6: PRJ-022 | C6: Design clash identified during 3D model review | D6: Low | E6: Eng. Manager | F6: 46227 | G6: Open | H6: 46249
A7: ISS-006 | B7: PRJ-001 | C7: Missing interface data from adjacent project | D7: Medium | E7: Project Manager | F7: 46192 | G7: Open | H7: 46235
A8: ISS-007 | B8: PRJ-004 | C8: Vendor document non-conformance | D8: Low | E8: Discipline Lead | F8: 46227 | G8: Open | H8: 46247
A9: ISS-008 | B9: PRJ-021 | C9: Field query awaiting engineering response | D9: Low | E9: Discipline Lead | F9: 46224 | G9: Open | H9: 46244
A10: ISS-009 | B10: PRJ-003 | C10: As-built discrepancy against design drawing | D10: High | E10: Eng. Manager | F10: 46247 | G10: Open | H10: 46269
A11: ISS-010 | B11: GLB-005 | C11: Vendor document non-conformance | D11: Medium | E11: Eng. Manager | F11: 46230 | G11: Open | H11: 46253
A12: ISS-011 | B12: GLB-004 | C12: Missing interface data from adjacent project | D12: Medium | E12: Discipline Lead | F12: 46230 | G12: Open | H12: 46274
A13: ISS-012 | B13: PRJ-020 | C13: Non-conformance report open against fabrication | D13: Low | E13: Eng. Manager | F13: 46210 | G13: Open | H13: 46233
... A17: ISS-016 | B17: PRJ-018 | C17: Missing interface data from adjacent project | D17: Medium | E17: Eng. Manager | F17: 46200 | G17: Open | H17: 46210

Sheet Actions
A1: ActionID | B1: ProjectID | C1: ActionDescription | D1: Owner | E1: DueDate | F1: Status | G1: IsOverdue
A2: ACT-001 | B2: PRJ-014 | C2: Confirm shutdown access dates with Operations | D2: Project Manager | E2: 46262 | F2: Open | G2: =IF(AND(E2<Config!$B$2,F2="Open"),TRUE,FALSE) -> FALSE
A3: ACT-002 | B3: PRJ-026 | C3: Finalise resource rebalancing plan | D3: Discipline Lead | E3: 46268 | F3: Open | G3: =IF(AND(E3<Config!$B$2,F3="Open"),TRUE,FALSE) -> FALSE
A4: ACT-003 | B4: PRJ-010 | C4: Close out HAZOP action item | D4: Project Manager | E4: 46240 | F4: Open | G4: =IF(AND(E4<Config!$B$2,F4="Open"),TRUE,FALSE) -> TRUE
A5: ACT-004 | B5: PRJ-003 | C5: Submit revised vendor data request | D5: Project Controls Lead | E5: 46247 | F5: Open | G5: =IF(AND(E5<Config!$B$2,F5="Open"),TRUE,FALSE) -> TRUE
A6: ACT-005 | B6: PRJ-021 | C6: Confirm shutdown access dates with Operations | D6: Eng. Manager | E6: 46240 | F6: Open | G6: =IF(AND(E6<Config!$B$2,F6="Open"),TRUE,FALSE) -> TRUE
A7: ACT-006 | B7: PRJ-015 | C7: Finalise resource rebalancing plan | D7: Project Manager | E7: 46276 | F7: Open | G7: =IF(AND(E7<Config!$B$2,F7="Open"),TRUE,FALSE) -> FALSE
A8: ACT-007 | B8: PRJ-011 | C8: Confirm shutdown access dates with Operations | D8: Eng. Manager | E8: 46265 | F8: Open | G8: =IF(AND(E8<Config!$B$2,F8="Open"),TRUE,FALSE) -> FALSE
A9: ACT-008 | B9: PRJ-022 | C9: Submit revised vendor data request | D9: Eng. Manager | E9: 46243 | F9: Open | G9: =IF(AND(E9<Config!$B$2,F9="Open"),TRUE,FALSE) -> TRUE
A10: ACT-009 | B10: PRJ-005 | C10: Close out HAZOP action item | D10: Discipline Lead | E10: 46270 | F10: Open | G10: =IF(AND(E10<Config!$B$2,F10="Open"),TRUE,FALSE) -> FALSE
A11: ACT-010 | B11: PRJ-004 | C11: Close out HAZOP action item | D11: Project Manager | E11: 46276 | F11: Open | G11: =IF(AND(E11<Config!$B$2,F11="Open"),TRUE,FALSE) -> FALSE
A12: ACT-011 | B12: PRJ-014 | C12: Confirm shutdown access dates with Operations | D12: Project Controls Lead | E12: 46263 | F12: Open | G12: =IF(AND(E12<Config!$B$2,F12="Open"),TRUE,FALSE) -> FALSE
A13: ACT-012 | B13: PRJ-007 | C13: Confirm shutdown access dates with Operations | D13: Project Controls Lead | E13: 46267 | F13: Open | G13: =IF(AND(E13<Config!$B$2,F13="Open"),TRUE,FALSE) -> FALSE
... A20: ACT-019 | B20: PRJ-026 | C20: Complete interface data exchange | D20: Eng. Manager | E20: 46278 | F20: Open | G20: =IF(AND(E20<Config!$B$2,F20="Open"),TRUE,FALSE) -> FALSE

Sheet ChangeRequests
A1: ChangeRequestID | B1: ProjectID | C1: Description | D1: Status | E1: RaisedDate | F1: Impact
A2: CR-001 | B2: PRJ-013 | C2: Extended metering skid scope to include prover loop | D2: Approved | E2: 46231 | F2: Scope
A3: CR-002 | B3: PRJ-020 | C3: Scope reduction following optioneering study | D3: Under Review | E3: 46210 | F3: Schedule
A4: CR-003 | B4: PRJ-011 | C4: Additional well slot scope addition | D4: Approved | E4: 46228 | F4: Cost
A5: CR-004 | B5: PRJ-024 | C5: Schedule extension request due to vendor delay | D5: Pending Approval | E5: 46218 | F5: Scope
A6: CR-005 | B6: PRJ-019 | C6: Budget increase request for long-lead items | D6: Under Review | E6: 46231 | F6: Schedule
A7: CR-006 | B7: PRJ-016 | C7: Extended metering skid scope to include prover loop | D7: Under Review | E7: 46218 | F7: Cost

Sheet Milestones
A1: MilestoneID | B1: ProjectID | C1: MilestoneName | D1: MilestoneType | E1: TargetDate | F1: Status | G1: ActualDate
A2: MS-001 | B2: PRJ-024 | C2: Basis of Design | D2: Milestone | E2: 46225 | F2: Done | G2: 46225
A3: MS-002 | B3: PRJ-024 | C3: HAZID Workshop | D3: Milestone | E3: 46234 | F3: Done | G3: 46234
A4: MS-003 | B4: PRJ-024 | C4: HAZOP Closeout | D4: Milestone | E4: 46251 | F4: Next
A5: MS-004 | B5: PRJ-024 | C5: Define Gate Readiness | D5: Gate | E5: 46256 | F5: At Risk
A6: MS-005 | B6: PRJ-024 | C6: Mechanical Design Complete | D6: Milestone | E6: 46259 | F6: In Progress
A7: MS-006 | B7: PRJ-024 | C7: Define Gate Approval | D7: Gate | E7: 46263 | F7: Upcoming
A8: MS-007 | B8: PRJ-021 | C8: Implementation Start | D8: Milestone | E8: 46269 | F8: On Track
A9: MS-008 | B9: PRJ-021 | C9: Shutdown Window Confirmed | D9: Milestone | E9: 46254 | F9: Done | G9: 46252
A10: MS-009 | B10: PRJ-021 | C10: Execute Gate Approval | D10: Gate | E10: 46336 | F10: On Track
A11: MS-010 | B11: PRJ-018 | C11: Concept Options Workshop | D11: Milestone | E11: 46291 | F11: Upcoming
A12: MS-011 | B12: PRJ-018 | C12: Assess Gate Review | D12: Gate | E12: 46389 | F12: Upcoming
A13: MS-012 | B13: PRJ-015 | C13: Basis of Design | D13: Milestone | E13: 46003 | F13: Done | G13: 46002
A14: MS-013 | B14: PRJ-015 | C14: HAZID Workshop | D14: Milestone | E14: 46091 | F14: Done | G14: 46093
A15: MS-014 | B15: PRJ-015 | C15: HAZOP Closeout | D15: Milestone | E15: 46178 | F15: Done | G15: 46180
A16: MS-015 | B16: PRJ-015 | C16: Define Gate Approval | D16: Gate | E16: 46266 | F16: Upcoming
A17: MS-016 | B17: PRJ-011 | C17: Detailed Design Complete | D17: Milestone | E17: 45928 | F17: Done | G17: 45929
A18: MS-017 | B18: PRJ-011 | C18: Procurement Complete | D18: Milestone | E18: 46029 | F18: Done | G18: 46033
A19: MS-018 | B19: PRJ-011 | C19: Construction Complete | D19: Milestone | E19: 46131 | F19: Done | G19: 46134
A20: MS-019 | B20: PRJ-011 | C20: Execute Gate Approval | D20: Gate | E20: 46232 | F20: Done | G20: 46234
A21: MS-020 | B21: GLB-003 | C21: Concept Options Workshop | D21: Milestone | E21: 46283 | F21: Upcoming
A22: MS-021 | B22: GLB-003 | C22: Assess Gate Review | D22: Gate | E22: 46392 | F22: Upcoming
A23: MS-022 | B23: PRJ-006 | C23: MDR Closeout | D23: Milestone | E23: 45834 | F23: Done | G23: 45837
A24: MS-023 | B24: PRJ-006 | C24: Lessons Learned Workshop | D24: Milestone | E24: 45982 | F24: Done | G24: 45982
A25: MS-024 | B25: PRJ-006 | C25: Archive Sign-off | D25: Milestone | E25: 46129 | F25: Done | G25: 46126
A26: MS-025 | B26: PRJ-009 | C26: MDR Closeout | D26: Milestone | E26: 45728 | F26: Done | G26: 45726
A27: MS-026 | B27: PRJ-009 | C27: Lessons Learned Workshop | D27: Milestone | E27: 45902 | F27: Done | G27: 45899
A28: MS-027 | B28: PRJ-009 | C28: Archive Sign-off | D28: Milestone | E28: 46075 | F28: Done | G28: 46075
A29: MS-028 | B29: PRJ-005 | C29: Concept Options Workshop | D29: Milestone | E29: 46232 | F29: Done | G29: 46232
A30: MS-029 | B30: PRJ-005 | C30: Assess Gate Review | D30: Gate | E30: 46342 | F30: Upcoming
A31: MS-030 | B31: PRJ-008 | C31: Concept Options Workshop | D31: Milestone | E31: 46257 | F31: In Progress
A32: MS-031 | B32: PRJ-008 | C32: Assess Gate Review | D32: Gate | E32: 46368 | F32: Upcoming
A33: MS-032 | B33: PRJ-013 | C33: Select Gate Review | D33: Gate | E33: 46230 | F33: Done | G33: 46229
A34: MS-033 | B34: PRJ-013 | C34: Preferred Concept Sign-off | D34: Milestone | E34: 46327 | F34: Upcoming
A35: MS-034 | B35: PRJ-019 | C35: Identify Gate Review | D35: Gate | E35: 46438 | F35: Upcoming
A36: MS-035 | B36: PRJ-023 | C36: Concept Options Workshop | D36: Milestone | E36: 46284 | F36: Upcoming
A37: MS-036 | B37: PRJ-023 | C37: Assess Gate Review | D37: Gate | E37: 46369 | F37: Upcoming
A38: MS-037 | B38: GLB-004 | C38: Select Gate Review | D38: Gate | E38: 46201 | F38: Done | G38: 46203
A39: MS-038 | B39: GLB-004 | C39: Preferred Concept Sign-off | D39: Milestone | E39: 46311 | F39: Upcoming
A40: MS-039 | B40: PRJ-001 | C40: Basis of Design | D40: Milestone | E40: 46134 | F40: Done | G40: 46135
...

Sheet Schedule_Activities
A1: ActivityID | B1: ProjectID | C1: ActivityName | D1: StartDate | E1: EndDate | F1: PctComplete
A2: GNT-001 | B2: PRJ-024 | C2: Process Design | D2: 45983 | E2: 46085 | F2: 100
A3: GNT-002 | B3: PRJ-024 | C3: Mechanical Design | D3: 46025 | E3: 46168 | F3: 75
A4: GNT-003 | B4: PRJ-024 | C4: Piping Design | D4: 46066 | E4: 46225 | F4: 86
A5: GNT-004 | B5: PRJ-024 | C5: E&I Design | D5: 46088 | E5: 46238 | F5: 80
A6: GNT-005 | B6: PRJ-024 | C6: Define Gate | D6: 46142 | E6: 46263 | F6: 52
A7: GNT-006 | B7: PRJ-021 | C7: Detailed Design | D7: 45787 | E7: 45979 | F7: 76
A8: GNT-007 | B8: PRJ-021 | C8: Procurement | D8: 45869 | E8: 46116 | F8: 65
A9: GNT-008 | B9: PRJ-021 | C9: Construction | D9: 45979 | E9: 46281 | F9: 69
A10: GNT-009 | B10: PRJ-021 | C10: Commissioning | D10: 46226 | E10: 46325 | F10: 18
A11: GNT-010 | B11: PRJ-021 | C11: Execute Gate | D11: 46309 | E11: 46336 | F11: 39
A12: GNT-011 | B12: PRJ-018 | C12: Concept Study | D12: 46193 | E12: 46328 | F12: 61
A13: GNT-012 | B13: PRJ-018 | C13: Options Assessment | D13: 46279 | E13: 46389 | F13: 73
... A102: GNT-101 | B102: PRJ-026 | C102: Execute Gate | D102: 46271 | E102: 46295 | F102: 5

Sheet SCurve_Monthly
A1: ProjectID | B1: MonthDate | C1: PlannedPct | D1: ActualPct
A2: PRJ-024 | B2: 46023 | C2: 11 | D2: 10
A3: PRJ-024 | B3: 46054 | C3: 20 | D3: 18
A4: PRJ-024 | B4: 46082 | C4: 29 | D4: 26
A5: PRJ-024 | B5: 46113 | C5: 39 | D5: 36
A6: PRJ-024 | B6: 46143 | C6: 49 | D6: 46
A7: PRJ-024 | B7: 46174 | C7: 59 | D7: 54
A8: PRJ-024 | B8: 46204 | C8: 66 | D8: 62
A9: PRJ-024 | B9: 46235 | C9: 71 | D9: 67
A10: PRJ-024 | B10: 46266 | C10: 72
A11: PRJ-024 | B11: 46296 | C11: 72
A12: PRJ-024 | B12: 46327 | C12: 72
A13: PRJ-024 | B13: 46357 | C13: 72
A14: PRJ-021 | B14: 46023 | C14: 32 | D14: 32
A15: PRJ-021 | B15: 46054 | C15: 39 | D15: 38
A16: PRJ-021 | B16: 46082 | C16: 45 | D16: 44
A17: PRJ-021 | B17: 46113 | C17: 51 | D17: 51
A18: PRJ-021 | B18: 46143 | C18: 58 | D18: 57
A19: PRJ-021 | B19: 46174 | C19: 64 | D19: 63
A20: PRJ-021 | B20: 46204 | C20: 69 | D20: 68
A21: PRJ-021 | B21: 46235 | C21: 73 | D21: 72
A22: PRJ-021 | B22: 46266 | C22: 77
A23: PRJ-021 | B23: 46296 | C23: 79
A24: PRJ-021 | B24: 46327 | C24: 80
A25: PRJ-021 | B25: 46357 | C25: 80
A26: PRJ-018 | B26: 46023 | C26: 0 | D26: 0
A27: PRJ-018 | B27: 46054 | C27: 0 | D27: 0
A28: PRJ-018 | B28: 46082 | C28: 0 | D28: 0
A29: PRJ-018 | B29: 46113 | C29: 0 | D29: 0
A30: PRJ-018 | B30: 46143 | C30: 0 | D30: 0
A31: PRJ-018 | B31: 46174 | C31: 0 | D31: 0
A32: PRJ-018 | B32: 46204 | C32: 2 | D32: 2
A33: PRJ-018 | B33: 46235 | C33: 25 | D33: 22
A34: PRJ-018 | B34: 46266 | C34: 69
A35: PRJ-018 | B35: 46296 | C35: 100
A36: PRJ-018 | B36: 46327 | C36: 100
A37: PRJ-018 | B37: 46357 | C37: 100
A38: PRJ-015 | B38: 46023 | C38: 11 | D38: 10
A39: PRJ-015 | B39: 46054 | C39: 18 | D39: 15
A40: PRJ-015 | B40: 46082 | C40: 24 | D40: 21
...
